<?xml version="1.0" encoding="utf-8"?>
<!-- This URDF was automatically created by SolidWorks to URDF Exporter! Originally created by Stephen Brawner (brawner@gmail.com) 
     Commit Version: 1.6.0-4-g7f85cfe  Build Version: 1.6.7995.38578
     For more information, please see http://wiki.ros.org/sw_urdf_exporter -->
<robot
  name="wsybot">
  <link
    name="base_link">
    <inertial>
      <origin
        xyz="-0.00320379 0.00004241 0.10854884"
        rpy="0 0 0" />
      <mass
        value="12.55685371" />
      <inertia
        ixx="0.29550389"
        ixy="-0.00003967"
        ixz="-0.03395022"
        iyy="0.30018885"
        iyz="0.00002645"
        izz="0.07985153" />
    </inertial>
    <visual>
      <origin
        xyz="0 0 0"
        rpy="0 0 0" />
      <geometry>
        <mesh
          filename="../meshes/base_link.STL" />
      </geometry>
      <material
        name="">
        <color
          rgba="1 1 1 1" />
      </material>
    </visual>
    <collision>
      <origin
        xyz="0 0 0"
        rpy="0 0 0" />
      <geometry>
        <box size="0.3 0.3 0.1" />
        <!-- <mesh
          filename="package://wsybot/meshes/base_link.STL" /> -->
      </geometry>
    </collision>
  </link>
  <link
    name="left_leg_roll_link">
    <inertial>
      <origin
        xyz="0.04106347 0.03787478 -0.06896879"
        rpy="0 0 0" />
      <mass
        value="1.78165449" />
      <inertia
        ixx="0.01287351"
        ixy="-0.00313362"
        ixz="0.00564327"
        iyy="0.01407438"
        iyz="0.00503339"
        izz="0.00728666" />
    </inertial>
    <visual>
      <origin
        xyz="0 0 0"
        rpy="0 0 0" />
      <geometry>
        <mesh
          filename="../meshes/left_leg_roll_link.STL" />
      </geometry>
      <material
        name="">
        <color
          rgba="0 0 0 1" />
      </material>
    </visual>
    <!-- <collision>
      <origin
        xyz="0 0 0"
        rpy="0 0 0" />
      <geometry>
        <mesh
          filename="package://wsybot/meshes/left_leg_roll_link.STL" />
      </geometry>
    </collision> -->
  </link>
  <joint
    name="left_leg_roll_joint"
    type="revolute">
    <origin
      xyz="-0.027 0.07 -0.01"
      rpy="0 0 0" />
    <parent
      link="base_link" />
    <child
      link="left_leg_roll_link" />
    <axis
      xyz="1 0 0" />
    <limit
      lower="-0.15"
      upper="0.7"
      effort="120"
      velocity="10.472" />
    <dynamics
      damping="0"
      friction="0" />
  </joint>
  <link
    name="left_leg_pitch_link">
    <inertial>
      <origin
        xyz="0.01342301 0.03124800 -0.07612561"
        rpy="0 0 0" />
      <mass
        value="0.71641931" />
      <inertia
        ixx="0.00623486"
        ixy="-0.00034223"
        ixz="0.00091218"
        iyy="0.00559904"
        iyz="0.00194088"
        izz="0.00122250" />
    </inertial>
    <visual>
      <origin
        xyz="0 0 0"
        rpy="0 0 0" />
      <geometry>
        <mesh
          filename="../meshes/left_leg_pitch_link.STL" />
      </geometry>
      <material
        name="">
        <color
          rgba="1 1 1 1" />
      </material>
    </visual>
    <!-- <collision>
      <origin
        xyz="0 0 0"
        rpy="0 0 0" />
      <geometry>
        <mesh
          filename="package://wsybot/meshes/left_leg_pitch_link.STL" />
      </geometry>
    </collision> -->
  </link>
  <joint
    name="left_leg_pitch_joint"
    type="revolute">
    <origin
      xyz="0.047 -0.0025 -0.075"
      rpy="0 0 0" />
    <parent
      link="left_leg_roll_link" />
    <child
      link="left_leg_pitch_link" />
    <axis
      xyz="0 -1 0" />
    <limit
      lower="-1"
      upper="1.2"
      effort="120"
      velocity="10.472" />
    <dynamics
      damping="0"
      friction="0" />
  </joint>
  <link
    name="left_leg_yaw_link">
    <inertial>
      <origin
        xyz="0.02393012 -0.03135613 -0.13508813"
        rpy="0 0 0" />
      <mass
        value="1.79523840" />
      <inertia
        ixx="0.03895026"
        ixy="0.00134307"
        ixz="0.00641611"
        iyy="0.03869567"
        iyz="-0.00758373"
        izz="0.00387311" />
    </inertial>
    <visual>
      <origin
        xyz="0 0 0"
        rpy="0 0 0" />
      <geometry>
        <mesh
          filename="../meshes/left_leg_yaw_link.STL" />
      </geometry>
      <material
        name="">
        <color
          rgba="0 0 0 1" />
      </material>
    </visual>
    <!-- <collision>
      <origin
        xyz="0 0 0"
        rpy="0 0 0" />
      <geometry>
        <mesh
          filename="package://wsybot/meshes/left_leg_yaw_link.STL" />
      </geometry>
    </collision> -->
  </link>
  <joint
    name="left_leg_yaw_joint"
    type="revolute">
    <origin
      xyz="0.025439 0.0435 -0.14427"
      rpy="0 0 0" />
    <parent
      link="left_leg_pitch_link" />
    <child
      link="left_leg_yaw_link" />
    <axis
      xyz="0.17365 0 -0.98481" />
    <limit
      lower="-1"
      upper="1"
      effort="27"
      velocity="5.5" />
    <dynamics
      damping="0"
      friction="0" />
  </joint>
  <link
    name="left_knee_link">
    <inertial>
      <origin
        xyz="-0.05441734 0.00833591 -0.20322786"
        rpy="0 0 0" />
      <mass
        value="0.82452135" />
      <inertia
        ixx="0.04448654"
        ixy="0.00066780"
        ixz="-0.01178119"
        iyy="0.04750783"
        iyz="0.00249632"
        izz="0.00363954" />
    </inertial>
    <visual>
      <origin
        xyz="0 0 0"
        rpy="0 0 0" />
      <geometry>
        <mesh
          filename="../meshes/left_knee_link.STL" />
      </geometry>
      <material
        name="">
        <color
          rgba="1 1 1 1" />
      </material>
    </visual>
    <collision>
      <origin
        xyz="0 0 0"
        rpy="0 0 0" />
      <geometry>
        <cylinder length="0.3" radius="0.08" />
        <!-- <mesh
          filename="package://wsybot/meshes/left_knee_link.STL" /> -->
      </geometry>
    </collision>
  </link>
  <joint
    name="left_knee_joint"
    type="revolute">
    <origin
      xyz="0.026655 0.0067 -0.15117"
      rpy="0 0 0" />
    <parent
      link="left_leg_yaw_link" />
    <child
      link="left_knee_link" />
    <axis
      xyz="0 1 0" />
    <limit
      lower="-0.4"
      upper="1.5"
      effort="120"
      velocity="10.472" />
    <dynamics
      damping="0"
      friction="0" />
  </joint>
  <link
    name="left_ankle_pitch_link">
    <inertial>
      <origin
        xyz="0.02342857 -0.01514997 -0.04370008"
        rpy="0 0 0" />
      <mass
        value="0.51356956" />
      <inertia
        ixx="0.00138393"
        ixy="0.00023036"
        ixz="0.00060294"
        iyy="0.00158552"
        iyz="-0.00042067"
        izz="0.00064396" />
    </inertial>
    <visual>
      <origin
        xyz="0 0 0"
        rpy="0 0 0" />
      <geometry>
        <mesh
          filename="../meshes/left_ankle_pitch_link.STL" />
      </geometry>
      <material
        name="">
        <color
          rgba="0 0 0 1" />
      </material>
    </visual>
    <!-- <collision>
      <origin
        xyz="0 0 0"
        rpy="0 0 0" />
      <geometry>
        <mesh
          filename="package://wsybot/meshes/left_ankle_pitch_link.STL" />
      </geometry>
    </collision> -->
  </link>
  <joint
    name="left_ankle_pitch_joint"
    type="revolute">
    <origin
      xyz="-0.077646 -0.027 -0.28978"
      rpy="0 0 0" />
    <parent
      link="left_knee_link" />
    <child
      link="left_ankle_pitch_link" />
    <axis
      xyz="0 -1 0" />
    <limit
      lower="-1"
      upper="1"
      effort="27"
      velocity="5.5" />
    <dynamics
      damping="0"
      friction="0" />
  </joint>
  <link
    name="left_ankle_roll_link">
    <inertial>
      <origin
        xyz="0.04368726 0 -0.03574426"
        rpy="0 0 0" />
      <mass
        value="0.55731183" />
      <inertia
        ixx="0.00105220"
        ixy="0.0"
        ixz="0.00100438"
        iyy="0.00396485"
        iyz="0.0"
        izz="0.00336644" />
    </inertial>
    <visual>
      <origin
        xyz="0 0 0"
        rpy="0 0 0" />
      <geometry>
        <mesh
          filename="../meshes/left_ankle_roll_link.STL" />
      </geometry>
      <material
        name="">
        <color
          rgba="1 1 1 1" />
      </material>
    </visual>
    <collision>
      <origin
        xyz="0 0 0"
        rpy="0 0 0" />
      <geometry>
        <mesh
          filename="../meshes/left_ankle_roll_link.STL" />
      </geometry>
    </collision>
  </link>
  <joint
    name="left_ankle_roll_joint"
    type="revolute">
    <origin
      xyz="-0.021 -0.019 -0.05"
      rpy="0 0 0" />
    <parent
      link="left_ankle_pitch_link" />
    <child
      link="left_ankle_roll_link" />
    <axis
      xyz="-1 0 0" />
    <limit
      lower="-0.5"
      upper="0.5"
      effort="27"
      velocity="5.5" />
    <dynamics
      damping="0"
      friction="0" />
  </joint>
  <link
    name="right_leg_roll_link">
    <inertial>
      <origin
        xyz="0.04127865 -0.03787215 -0.06896401"
        rpy="0 0 0" />
      <mass
        value="1.78177814" />
      <inertia
        ixx="0.01287354"
        ixy="0.00315071"
        ixz="0.00567387"
        iyy="0.01411116"
        iyz="-0.00503339"
        izz="0.00732343" />
    </inertial>
    <visual>
      <origin
        xyz="0 0 0"
        rpy="0 0 0" />
      <geometry>
        <mesh
          filename="../meshes/right_leg_roll_link.STL" />
      </geometry>
      <material
        name="">
        <color
          rgba="0 0 0 1" />
      </material>
    </visual>
    <!-- <collision>
      <origin
        xyz="0 0 0"
        rpy="0 0 0" />
      <geometry>
        <mesh
          filename="package://wsybot/meshes/right_leg_roll_link.STL" />
      </geometry>
    </collision> -->
  </link>
  <joint
    name="right_leg_roll_joint"
    type="revolute">
    <origin
      xyz="-0.027 -0.07 -0.01"
      rpy="0 0 0" />
    <parent
      link="base_link" />
    <child
      link="right_leg_roll_link" />
    <axis
      xyz="1 0 0" />
    <limit
      lower="-0.7"
      upper="0.15"
      effort="120"
      velocity="10.472" />
    <dynamics
      damping="0"
      friction="0" />
  </joint>
  <link
    name="right_leg_pitch_link">
    <inertial>
      <origin
        xyz="0.01342299 -0.03124800 -0.07612561"
        rpy="0 0 0" />
      <mass
        value="0.71641931" />
      <inertia
        ixx="0.00623486"
        ixy="0.00034223"
        ixz="0.00091217"
        iyy="0.00559904"
        iyz="-0.00194088"
        izz="0.00122250" />
    </inertial>
    <visual>
      <origin
        xyz="0 0 0"
        rpy="0 0 0" />
      <geometry>
        <mesh
          filename="../meshes/right_leg_pitch_link.STL" />
      </geometry>
      <material
        name="">
        <color
          rgba="1 1 1 1" />
      </material>
    </visual>
    <!-- <collision>
      <origin
        xyz="0 0 0"
        rpy="0 0 0" />
      <geometry>
        <mesh
          filename="package://wsybot/meshes/right_leg_pitch_link.STL" />
      </geometry>
    </collision> -->
  </link>
  <joint
    name="right_leg_pitch_joint"
    type="revolute">
    <origin
      xyz="0.047 0.0025 -0.075"
      rpy="0 0 0" />
    <parent
      link="right_leg_roll_link" />
    <child
      link="right_leg_pitch_link" />
    <axis
      xyz="0 1 0" />
    <limit
      lower="-1.2"
      upper="1"
      effort="120"
      velocity="10.472" />
    <dynamics
      damping="0"
      friction="0" />
  </joint>
  <link
    name="right_leg_yaw_link">
    <inertial>
      <origin
        xyz="0.02371590 0.03135613 -0.13512590"
        rpy="0 0 0" />
      <mass
        value="1.79523840" />
      <inertia
        ixx="0.03897121"
        ixy="-0.00133171"
        ixz="0.00635855"
        iyy="0.03869567"
        iyz="0.00758573"
        izz="0.00385216" />
    </inertial>
    <visual>
      <origin
        xyz="0 0 0"
        rpy="0 0 0" />
      <geometry>
        <mesh
          filename="../meshes/right_leg_yaw_link.STL" />
      </geometry>
      <material
        name="">
        <color
          rgba="0 0 0 1" />
      </material>
    </visual>
    <!-- <collision>
      <origin
        xyz="0 0 0"
        rpy="0 0 0" />
      <geometry>
        <mesh
          filename="package://wsybot/meshes/right_leg_yaw_link.STL" />
      </geometry>
    </collision> -->
  </link>
  <joint
    name="right_leg_yaw_joint"
    type="revolute">
    <origin
      xyz="0.025439 -0.0435 -0.14427"
      rpy="0 0 0" />
    <parent
      link="right_leg_pitch_link" />
    <child
      link="right_leg_yaw_link" />
    <axis
      xyz="0.17365 0 -0.98481" />
    <limit
      lower="-1"
      upper="1"
      effort="27"
      velocity="5.5" />
    <dynamics
      damping="0"
      friction="0" />
  </joint>
  <link
    name="right_knee_link">
    <inertial>
      <origin
        xyz="-0.05441734 -0.00833591 -0.20322784"
        rpy="0 0 0" />
      <mass
        value="0.82452135" />
      <inertia
        ixx="0.04448653"
        ixy="-0.00066780"
        ixz="-0.01178120"
        iyy="0.04750783"
        iyz="-0.00249632"
        izz="0.00363954" />
    </inertial>
    <visual>
      <origin
        xyz="0 0 0"
        rpy="0 0 0" />
      <geometry>
        <mesh
          filename="../meshes/right_knee_link.STL" />
      </geometry>
      <material
        name="">
        <color
          rgba="1 1 1 1" />
      </material>
    </visual>
    <collision>
      <origin
        xyz="0 0 0"
        rpy="0 0 0" />
      <geometry>
        <cylinder length="0.3" radius="0.08" />
        <!-- <mesh
          filename="package://wsybot/meshes/right_knee_link.STL" /> -->
      </geometry>
    </collision>
  </link>
  <joint
    name="right_knee_joint"
    type="revolute">
    <origin
      xyz="0.026655 -0.0067 -0.15117"
      rpy="0 0 0" />
    <parent
      link="right_leg_yaw_link" />
    <child
      link="right_knee_link" />
    <axis
      xyz="0 -1 0" />
    <limit
      lower="-1.5"
      upper="0.4"
      effort="120"
      velocity="10.472" />
    <dynamics
      damping="0"
      friction="0" />
  </joint>
  <link
    name="right_ankle_pitch_link">
    <inertial>
      <origin
        xyz="0.02342857 0.01514997 -0.04370006"
        rpy="0 0 0" />
      <mass
        value="0.51356954" />
      <inertia
        ixx="0.00138392"
        ixy="-0.00023036"
        ixz="0.00060294"
        iyy="0.00158552"
        iyz="0.00042067"
        izz="0.00064396" />
    </inertial>
    <visual>
      <origin
        xyz="0 0 0"
        rpy="0 0 0" />
      <geometry>
        <mesh
          filename="../meshes/right_ankle_pitch_link.STL" />
      </geometry>
      <material
        name="">
        <color
          rgba="0 0 0 1" />
      </material>
    </visual>
    <!-- <collision>
      <origin
        xyz="0 0 0"
        rpy="0 0 0" />
      <geometry>
        <mesh
          filename="package://wsybot/meshes/right_ankle_pitch_link.STL" />
      </geometry>
    </collision> -->
  </link>
  <joint
    name="right_ankle_pitch_joint"
    type="revolute">
    <origin
      xyz="-0.077646 0.027 -0.28978"
      rpy="0 0 0" />
    <parent
      link="right_knee_link" />
    <child
      link="right_ankle_pitch_link" />
    <axis
      xyz="0 1 0" />
    <limit
      lower="-1"
      upper="1"
      effort="27"
      velocity="5.5" />
    <dynamics
      damping="0"
      friction="0" />
  </joint>
  <link
    name="right_ankle_roll_link">
    <inertial>
      <origin
        xyz="0.04368726 0.0 -0.03574426"
        rpy="0 0 0" />
      <mass
        value="0.55731183" />
      <inertia
        ixx="0.00105220"
        ixy="0.0"
        ixz="0.00100438"
        iyy="0.00396485"
        iyz="0.0"
        izz="0.00336644" />
    </inertial>
    <visual>
      <origin
        xyz="0 0 0"
        rpy="0 0 0" />
      <geometry>
        <mesh
          filename="../meshes/right_ankle_roll_link.STL" />
      </geometry>
      <material
        name="">
        <color
          rgba="1 1 1 1" />
      </material>
    </visual>
    <collision>
      <origin
        xyz="0 0 0"
        rpy="0 0 0" />
      <geometry>
        <mesh
          filename="../meshes/right_ankle_roll_link.STL" />
      </geometry>
    </collision>
  </link>
  <joint
    name="right_ankle_roll_joint"
    type="revolute">
    <origin
      xyz="-0.021 0.019 -0.05"
      rpy="0 0 0" />
    <parent
      link="right_ankle_pitch_link" />
    <child
      link="right_ankle_roll_link" />
    <axis
      xyz="-1 0 0" />
    <limit
      lower="-0.5"
      upper="0.5"
      effort="27"
      velocity="5.5" />
    <dynamics
      damping="0"
      friction="0" />
  </joint>
</robot>