<mujoco model="wsybot">
    <compiler angle="radian" meshdir="../meshes/"  eulerseq="zyx" />
        <option timestep='0.001' iterations='50' solver='PGS' gravity='0 0 -9.81'>
        <flag sensornoise="enable" frictionloss="enable"/>
        </option>

    <size njmax="500" nconmax="100" />

        <visual>
            <quality shadowsize='4096'/>
            <map znear='0.05'/>
        </visual>
        <default>
            <joint limited='true'/>
            <motor ctrllimited='true'/>
            <geom  condim='4' contype='1' conaffinity='15' solref='0.0012' friction='0.9 0.2 0.2'/>
            <equality solref='0.0012'/>
            <default class='leg_joint_param'>
                <joint damping="0.01" frictionloss="0.01" armature="0.01"/>
            </default>
        </default>
    <statistic meansize="0.164352" extent="1.07561" center="-0.00820016 -1.48012e-05 -0.160784"/>

    <asset>
        <mesh name="base_link" file="../meshes/base_link.STL" />
        <mesh name="left_leg_roll_link" file="../meshes/left_leg_roll_link.STL" />
        <mesh name="left_leg_pitch_link" file="../meshes/left_leg_pitch_link.STL" />
        <mesh name="left_leg_yaw_link" file="../meshes/left_leg_yaw_link.STL" />
        <mesh name="left_knee_link" file="../meshes/left_knee_link.STL" />
        <mesh name="left_ankle_pitch_link" file="../meshes/left_ankle_pitch_link.STL" />
        <mesh name="left_ankle_roll_link" file="../meshes/left_ankle_roll_link.STL" />
        <mesh name="right_leg_roll_link" file="../meshes/right_leg_roll_link.STL" />
        <mesh name="right_leg_pitch_link" file="../meshes/right_leg_pitch_link.STL" />
        <mesh name="right_leg_yaw_link" file="../meshes/right_leg_yaw_link.STL" />
        <mesh name="right_knee_link" file="../meshes/right_knee_link.STL" />
        <mesh name="right_ankle_pitch_link" file="../meshes/right_ankle_pitch_link.STL" />
        <mesh name="right_ankle_roll_link" file="../meshes/right_ankle_roll_link.STL" />
        <material name="matplane" reflectance="0.3" texture="texplane" texrepeat="1 1" texuniform="true"/>
        <material name="matgeom" texture="texgeom" texuniform="true" rgba="0.8 0.6 .4 1"/>
        <texture name="texplane" type="2d" builtin="checker" rgb1=".2 .3 .4" rgb2=".1 0.15 0.2" width="512" height="512" mark="cross" markrgb=".8 .8 .8"/>  
        <texture name="texgeom" type="cube" builtin="flat" mark="cross" width="127" height="1278" rgb1="0.8 0.6 0.4" rgb2="0.8 0.6 0.4" markrgb="1 1 1" random="0.01"/>
        <texture type="skybox" builtin="gradient" rgb1="1 1 1" rgb2=".6 .8 1" width="256" height="256"/>
    </asset>

    <worldbody>

        <light directional="true" diffuse=".4 .4 .4" specular="0.1 0.1 0.1" pos="0 0 3.0" dir="0 0 -1" castshadow="false"/>
        <light directional="true" diffuse=".6 .6 .6" specular="0.2 0.2 0.2" pos="0 0 4" dir="0 0 -1"/>
        <geom name="ground" type="plane" size="0 0 1" pos="0.001 0 0" quat="1 0 0 0" material="matplane" condim="1" conaffinity='15'/>
        <body name="base_link" pos="0 0 0.778">

        <!-- <geom size="0.15 0.15 0.05" type="box" rgba="1 1 1 1" /> -->

            <inertial pos="-0.0032038 4.241e-05 0.10855" quat="0.996275 -0.00304285 0.0761248 -0.0404088" mass="12.557" diaginertia="0.300722 0.300186 0.0746335" />
            <joint name="floating_base_joint" type="free" />
            <site name='imu' size='0.01' pos='0.0 0 0.0' quat='1 0 0 0'/>
            <geom type="mesh" contype="1" conaffinity="0" group="1" rgba="1 1 1 1" mesh="base_link" />

            <body name="left_leg_roll_link" pos="-0.027 0.07 -0.01">
                <inertial pos="0.0410635 0.0378748 -0.0689688" quat="0.617277 -0.047971 -0.33358 0.71091" mass="1.78165" diaginertia="0.0167795 0.0163768 0.00107828" />
                <joint name="left_leg_roll_joint" pos="0 0 0" axis="1 0 0" limited="true" range="-0.15 0.7" />
                <geom type="mesh" contype="0" conaffinity="0" group="1" rgba="0 0 0 1" mesh="left_leg_roll_link" />
                <body name="left_leg_pitch_link" pos="0.047 -0.0025 -0.075">
                    <inertial pos="0.013423 0.031248 -0.0761256" quat="0.980311 0.177184 -0.0857682 0.0155115" mass="0.716419" diaginertia="0.0063957 0.00633553 0.00032517" />
                    <joint name="left_leg_pitch_joint" pos="0 0 0" axis="0 -1 0" limited="true" range="-1 1.2" />
                    <geom type="mesh" contype="0" conaffinity="0" group="1" rgba="1 1 1 1" mesh="left_leg_pitch_link" />
                    <body name="left_leg_yaw_link" pos="0.025439 0.0435 -0.14427">
                        <inertial pos="0.0239301 -0.0313561 -0.135088" quat="0.706051 -0.132733 0.0097375 0.695543" mass="1.79524" diaginertia="0.0402758 0.040087 0.00115623" />
                        <joint name="left_leg_yaw_joint" pos="0 0 0" axis="0.17365 0 -0.984808" limited="true" range="-1 1" />
                        <geom type="mesh" contype="0" conaffinity="0" group="1" rgba="0 0 0 1" mesh="left_leg_yaw_link" />
                        <body name="left_knee_link" pos="0.026655 0.0067 -0.15117">
                            <inertial pos="-0.0544173 0.00833591 -0.203228" quat="0.680133 0.113705 0.0693323 0.720891" mass="0.824521" diaginertia="0.0476494 0.0476409 0.000343592" />
                            <joint name="left_knee_joint" pos="0 0 0" axis="0 1 0" limited="true" range="-0.4 1.5" />
                            <!-- <geom size="0.08 0.15" type="cylinder" rgba="1 1 1 1" /> -->
                            <geom type="mesh" contype="0" conaffinity="0" group="1" rgba="1 1 1 1" mesh="left_knee_link" />
                            <body name="left_ankle_pitch_link" pos="-0.077646 -0.027 -0.28978">
                                <inertial pos="0.0234286 -0.01515 -0.0437001" quat="0.647432 -0.289962 -0.0421037 0.703549" mass="0.51357" diaginertia="0.00174609 0.00172064 0.000146679" />
                                <joint name="left_ankle_pitch_joint" pos="0 0 0" axis="0 -1 0" limited="true" range="-1 1" />
                                <geom type="mesh" contype="0" conaffinity="0" group="1" rgba="0 0 0 1" mesh="left_ankle_pitch_link" />
                                <body name="left_ankle_roll_link" pos="-0.021 -0.019 -0.05">
                                    <inertial pos="0.0436873 0 -0.0357443" quat="0.403155 0.580918 0.580918 0.403155" mass="0.557312" diaginertia="0.00396485 0.00374154 0.000677097" />
                                    <joint name="left_ankle_roll_joint" pos="0 0 0" axis="-1 0 0" limited="true" range="-0.5 0.5" />
                                    <geom type="mesh" rgba="1 1 1 1" mesh="left_ankle_roll_link" />
                                </body>
                            </body>
                        </body>
                    </body>
                </body>
            </body>
            <body name="right_leg_roll_link" pos="-0.027 -0.07 -0.01">
                <inertial pos="0.0412787 -0.0378722 -0.068964" quat="0.711127 -0.334128 -0.0491603 0.616636" mass="1.78178" diaginertia="0.0168166 0.0164145 0.00107699" />
                <joint name="right_leg_roll_joint" pos="0 0 0" axis="1 0 0" limited="true" range="-0.7 0.15" />
                <geom type="mesh" contype="0" conaffinity="0" group="1" rgba="0 0 0 1" mesh="right_leg_roll_link" />
                <body name="right_leg_pitch_link" pos="0.047 0.0025 -0.075">
                    <inertial pos="0.013423 -0.031248 -0.0761256" quat="0.980311 -0.177187 -0.0857627 -0.0154849" mass="0.716419" diaginertia="0.0063957 0.00633553 0.000325173" />
                    <joint name="right_leg_pitch_joint" pos="0 0 0" axis="0 1 0" limited="true" range="-1.2 1" />
                    <geom type="mesh" contype="0" conaffinity="0" group="1" rgba="1 1 1 1" mesh="right_leg_pitch_link" />
                    <body name="right_leg_yaw_link" pos="0.025439 -0.0435 -0.14427">
                        <inertial pos="0.0237159 0.0313561 -0.135126" quat="0.693641 0.00993871 -0.132193 0.708017" mass="1.79524" diaginertia="0.0402758 0.040087 0.00115623" />
                        <joint name="right_leg_yaw_joint" pos="0 0 0" axis="0.17365 0 -0.984808" limited="true" range="-1 1" />
                        <geom type="mesh" contype="0" conaffinity="0" group="1" rgba="0 0 0 1" mesh="right_leg_yaw_link" />
                        <body name="right_knee_link" pos="0.026655 -0.0067 -0.15117">
                            <inertial pos="-0.0544173 -0.00833591 -0.203228" quat="0.720904 0.0693302 0.113707 0.680119" mass="0.824521" diaginertia="0.0476494 0.0476409 0.000343587" />
                            <joint name="right_knee_joint" pos="0 0 0" axis="0 -1 0" limited="true" range="-1.5 0.4" />
                            <!-- <geom size="0.08 0.15" type="cylinder" rgba="1 1 1 1" /> -->
                            <geom type="mesh" contype="0" conaffinity="0" group="1" rgba="1 1 1 1" mesh="right_knee_link" />
                            <body name="right_ankle_pitch_link" pos="-0.077646 0.027 -0.28978">
                                <inertial pos="0.0234286 0.01515 -0.0437001" quat="0.703549 -0.0421043 -0.289963 0.647431" mass="0.51357" diaginertia="0.00174609 0.00172064 0.000146676" />
                                <joint name="right_ankle_pitch_joint" pos="0 0 0" axis="0 1 0" limited="true" range="-1 1" />
                                <geom type="mesh" contype="0" conaffinity="0" group="1" rgba="0 0 0 1" mesh="right_ankle_pitch_link" />
                                <body name="right_ankle_roll_link" pos="-0.021 0.019 -0.05">
                                    <inertial pos="0.0436873 0 -0.0357443" quat="0.403155 0.580918 0.580918 0.403155" mass="0.557312" diaginertia="0.00396485 0.00374154 0.000677097" />
                                    <joint name="right_ankle_roll_joint" pos="0 0 0" axis="-1 0 0" limited="true" range="-0.5 0.5" />
                                    <geom type="mesh" rgba="1 1 1 1" mesh="right_ankle_roll_link" />
                                </body>
                            </body>
                        </body>
                    </body>
                </body>
            </body>
        </body>
    </worldbody>

    <actuator>

      <motor name="left_leg_roll_joint" joint="left_leg_roll_joint" gear="1" ctrllimited="true" ctrlrange="-120 120"/>
      <motor name="left_leg_pitch_joint" joint="left_leg_pitch_joint" gear="1" ctrllimited="true" ctrlrange="-120 120"/>
      <motor name="left_leg_yaw_joint" joint="left_leg_yaw_joint" gear="1" ctrllimited="true" ctrlrange="-27 27"/>
      <motor name="left_knee_joint" joint="left_knee_joint" gear="1" ctrllimited="true" ctrlrange="-120 120"/>
      <motor name="left_ankle_pitch_joint" joint="left_ankle_pitch_joint" gear="1" ctrllimited="true" ctrlrange="-27 27"/>
      <motor name="left_ankle_roll_joint" joint="left_ankle_roll_joint" gear="1" ctrllimited="true" ctrlrange="-27 27"/>

      <motor name="right_leg_roll_joint" joint="right_leg_roll_joint" gear="1" ctrllimited="true" ctrlrange="-120 120"/>
      <motor name="right_leg_pitch_joint" joint="right_leg_pitch_joint" gear="1" ctrllimited="true" ctrlrange="-120 120"/>
      <motor name="right_leg_yaw_joint" joint="right_leg_yaw_joint" gear="1" ctrllimited="true" ctrlrange="-27 27"/>
      <motor name="right_knee_joint" joint="right_knee_joint" gear="1" ctrllimited="true" ctrlrange="-120 120"/>
      <motor name="right_ankle_pitch_joint" joint="right_ankle_pitch_joint" gear="1" ctrllimited="true" ctrlrange="-27 27"/>
      <motor name="right_ankle_roll_joint" joint="right_ankle_roll_joint" gear="1" ctrllimited="true" ctrlrange="-27 27"/>
      
    </actuator>

     <sensor>
        
      <framequat     name='orientation' objtype='site' noise='0.001' objname='imu'/>
        <framepos     name='position' objtype='site' noise='0.001' objname='imu'/>
        <gyro          name='angular-velocity'    site='imu' noise='0.005' cutoff='34.9'/>
        <velocimeter   name='linear-velocity'     site='imu' noise='0.001' cutoff='30'/>
        <accelerometer name='linear-acceleration' site='imu' noise='0.005' cutoff='157'/>
        <magnetometer  name='magnetometer'        site='imu'/>

    </sensor>


</mujoco>
